<?xml version='1.0'?>
<sdf version='1.6'>
<model name="hammer">
<static>false</static>
<pose> 0 0 0.775 0 0 0 </pose>

<link name='tool'>
	<pose>0.0247 0.0000 0.6880 0.000 -1.57 0.000</pose>
	<inertial>
		<pose>0.1785 -0.0001 0.0002 0 0 0</pose>
		<mass>0.1219</mass>
	</inertial>
	<collision name='tool_collision'>
		<geometry>
			<mesh><uri>model://tool_hammering_nail/tool.dae</uri></mesh>
		</geometry>
	</collision>
	<visual name='tool_visual'>
		<geometry>
			<mesh><uri>model://tool_hammering_nail/tool.dae</uri></mesh>
		</geometry>
	</visual>
	<sensor name='tool_contact' type='contact'>
		<plugin filename="libnail_collision.so" name="nail_collision" />
		<contact>
			<collision>tool_collision</collision>
		</contact>
	</sensor>
</link>

<model name="elbow_model">
	<pose>-0.1 0.0000 0.25 0 0 0</pose>
	<static>true</static>
	<link name="elbow_link">
		<pose>0 0 0 0 0 0</pose>
		<visual name="elbow_visual">
			<geometry><sphere>
				<radius>0.005</radius>
			</sphere></geometry>
		</visual>
	</link>
</model>

	<joint name="joint_elbow" type="revolute">
		<parent>tool</parent>
		<child>elbow_link</child>
		<axis>
			<xyz>0 1 0</xyz>
			<use_parent_model_frame>1</use_parent_model_frame>
			<dynamics>
				<friction>0.1</friction>
			</dynamics>
		</axis>
	</joint>

<plugin filename="libhammer.so" name="hammer"/>

</model>
</sdf>
