<?xml version='1.0'?>
<sdf version='1.6'>
<model name="cutter">
<static>false</static>
<pose> 0 0 0 0 0 0 </pose>

<link name='tool'>
	<pose>0.6000 0 0.92 0.000 -1.57 1.57</pose>
	<inertial>
		<pose>-0.0002 0.1785 0.0001 0 0 0</pose>
		<mass>0.1219</mass>
	</inertial>
	<collision name='tool_collision'>
		<geometry>
			<mesh><uri>model://tool_cutting_lasagna/tool.dae</uri></mesh>
		</geometry>
	</collision>
	<visual name='tool_visual'>
		<geometry>
			<mesh><uri>model://tool_cutting_lasagna/tool.dae</uri></mesh>
		</geometry>
	</visual>
	<sensor name='tool_contact' type='contact'>
		<plugin filename="liblasagna_collision.so" name="lasagna_collision" />
		<contact>
			<collision>tool_collision</collision>
		</contact>
	</sensor>
</link>

<model name="elbow_model">
	<pose>0.30 -0.1926 0.8182 0 0 0</pose>
	<static>true</static>
	<link name="elbow_link">
		<pose>0 0 0 0 0 0</pose>
		<visual name="elbow_visual">
			<geometry><sphere>
				<radius>0.005</radius>
			</sphere></geometry>
		</visual>
	</link>
</model>

	<joint name="joint_elbow" type="prismatic">
		<parent>tool</parent>
		<child>elbow_link</child>
		<axis>
			<xyz>1 0 0</xyz>
			<use_parent_model_frame>1</use_parent_model_frame>
			<dynamics>
				<friction>0.1</friction>
			</dynamics>
		</axis>
	</joint>

<model name="action_bottom_model">
	<pose>0 0 0 0 0 0</pose>
	<link name="action_bottom_link">
		<pose>0.6000 0.0000 0.7751 0 0 0</pose>
		<visual name="action_bottom_visual">
			<geometry>
				<sphere>
					<radius>0.005</radius>
				</sphere>
			</geometry>
			<material>
				<script>
					<uri>file://media/materials/scripts/gazebo.material</uri>
					<name>Gazebo/Green</name>
				</script>
			</material>
		</visual>
	</link>
</model>

<joint name="joint_action_bottom" type="revolute">
	<parent>tool</parent>
	<child>action_bottom_link</child>
	<axis>
		<xyz>0 1 0</xyz>
		<use_parent_model_frame>1</use_parent_model_frame>
		<dynamics>
			<friction>0.1</friction>
		</dynamics>
	</axis>
</joint>

<plugin filename="libcut.so" name="cut"/>

</model>
</sdf>
