<?xml version='1.0'?>
<sdf version='1.6'>
<model name="winebottle">
<static>false</static>
<pose> 0 0 0 0 0 0 </pose>

<link name='tool'>
	<pose>0.5 -0.15 0.82 0 0 0</pose>
	<inertial>
		<pose>-0.0000 0.0074 0.0003 0 0 0</pose>
		<mass>0.2759</mass>
	</inertial>
	<collision name='tool_collision'>
		<geometry>
			<mesh><uri>model://tool_rolling_dough/tool.dae</uri></mesh>
		</geometry>
	</collision>
	<visual name='tool_visual'>
		<geometry>
			<mesh><uri>model://tool_rolling_dough/tool.dae</uri></mesh>
		</geometry>
	</visual>
	<sensor name='tool_contact' type='contact'>
		<plugin filename="libdough_collision.so" name="dough_collision" />
		<contact>
			<collision>tool_collision</collision>
		</contact>
	</sensor>
</link>

<joint name="joint_container_bottom" type="revolute">
	<parent>tool</parent>
	<child>action_centre_link</child>
	<axis>
		<xyz>1 0 0</xyz>
		<use_parent_model_frame>1</use_parent_model_frame>
		<dynamics>
			<friction>0.1</friction>
		</dynamics>
	</axis>
</joint>

<model name="action_centre_model">
	<pose>0 0 0 0 0 0</pose>
	<link name="action_centre_link">
		<pose>0.5 0 0.84 0 0 0</pose>
		<visual name="action_centre_visual">
			<geometry>
				<sphere>
					<radius>0.005</radius>
				</sphere>
			</geometry>	
			<material>
				<script>
					<uri>file://media/materials/scripts/gazebo.material</uri>
					<name>Gazebo/Green</name>
				</script>
			</material>					
		</visual>
	</link>
</model>

<plugin filename="libroll.so" name="roll"/>

</model>
</sdf>
